{
 "cells": [
  {
   "cell_type": "code",
   "execution_count": 1,
   "metadata": {
    "collapsed": false
   },
   "outputs": [],
   "source": [
    "import sys\n",
    "sys.path.append('../')\n",
    "import numpy as np\n",
    "import pandas as pd\n",
    "import matplotlib.pyplot as plt\n",
    "%matplotlib inline\n",
    "import scripts.read_land_use_no_gdal as rlu\n",
    "import scripts.read_image_data_scaleable as rid"
   ]
  },
  {
   "cell_type": "code",
   "execution_count": 2,
   "metadata": {
    "collapsed": false
   },
   "outputs": [],
   "source": [
    "# from importlib import reload\n",
    "# reload(rid)"
   ]
  },
  {
   "cell_type": "code",
   "execution_count": 3,
   "metadata": {
    "collapsed": false
   },
   "outputs": [],
   "source": [
    "polygon = \"POLYGON ((144.0229424345357 -37.55299953752239, 144.02019905996406 -37.97282887730929, 144.6632499098556 -37.972670022747636, 144.66240633494579 -37.552454710108975, 144.0229424345357 -37.55299953752239))\"\n",
    "array, classes = rlu.read_land_use(da_shapefile=\"SDM324649_full/ll_gda94/sde_shape/whole/VIC/CATCHMENTS/layer/landuse_2014.shp\",\n",
    "                  resolution=(2387, 1976),\n",
    "                  area_filter=polygon,\n",
    "                  buffer=-0.0001,\n",
    "                  processes=8)"
   ]
  },
  {
   "cell_type": "code",
   "execution_count": 4,
   "metadata": {
    "collapsed": false
   },
   "outputs": [],
   "source": [
    "# plt.imshow(array)"
   ]
  },
  {
   "cell_type": "code",
   "execution_count": 5,
   "metadata": {
    "collapsed": false,
    "scrolled": true
   },
   "outputs": [
    {
     "name": "stdout",
     "output_type": "stream",
     "text": [
      "reading data...\n",
      "reading new timestamps...\n",
      "interpolating images...\n",
      "storing sets...\n",
      "combining sets...\n"
     ]
    },
    {
     "name": "stderr",
     "output_type": "stream",
     "text": [
      "Exception ignored in: <bound method Shelf.__del__ of <shelve.DbfilenameShelf object at 0x7f0ba3ff19b0>>\n",
      "Traceback (most recent call last):\n",
      "  File \"/home/mithrillion/anaconda3/lib/python3.5/shelve.py\", line 162, in __del__\n",
      "    self.close()\n",
      "  File \"/home/mithrillion/anaconda3/lib/python3.5/shelve.py\", line 144, in close\n",
      "    self.sync()\n",
      "Exception ignored in: <bound method Shelf.__del__ of <shelve.DbfilenameShelf object at 0x7f0ba3fe6828>>\n",
      "Traceback (most recent call last):\n",
      "  File \"/home/mithrillion/anaconda3/lib/python3.5/shelve.py\", line 172, in sync\n",
      "  File \"/home/mithrillion/anaconda3/lib/python3.5/shelve.py\", line 162, in __del__\n",
      "    self.dict.sync()\n",
      "  File \"/home/mithrillion/anaconda3/lib/python3.5/dbm/dumb.py\", line 124, in _commit\n",
      "    self.close()\n",
      "  File \"/home/mithrillion/anaconda3/lib/python3.5/shelve.py\", line 144, in close\n",
      "    self._chmod(self._dirfile)\n",
      "  File \"/home/mithrillion/anaconda3/lib/python3.5/dbm/dumb.py\", line 270, in _chmod\n",
      "    self.sync()\n",
      "  File \"/home/mithrillion/anaconda3/lib/python3.5/shelve.py\", line 172, in sync\n",
      "    self._os.chmod(file, self._mode)\n",
      "    self.dict.sync()\n",
      "  File \"/home/mithrillion/anaconda3/lib/python3.5/dbm/dumb.py\", line 124, in _commit\n",
      "FileNotFoundError: [Errno 2] No such file or directory: 'models/area3/shelves/old/pixels.dir'\n",
      "    self._chmod(self._dirfile)\n",
      "  File \"/home/mithrillion/anaconda3/lib/python3.5/dbm/dumb.py\", line 270, in _chmod\n",
      "    self._os.chmod(file, self._mode)\n",
      "FileNotFoundError: [Errno 2] No such file or directory: 'models/area3/shelves/old/pixels.dir'\n",
      "Exception ignored in: <bound method Shelf.__del__ of <shelve.DbfilenameShelf object at 0x7f0ba3ff1a58>>\n",
      "Traceback (most recent call last):\n",
      "  File \"/home/mithrillion/anaconda3/lib/python3.5/shelve.py\", line 162, in __del__\n",
      "    self.close()\n",
      "  File \"/home/mithrillion/anaconda3/lib/python3.5/shelve.py\", line 146, in close\n",
      "    self.dict.close()\n",
      "  File \"/home/mithrillion/anaconda3/lib/python3.5/dbm/dumb.py\", line 262, in close\n",
      "    self._commit()\n",
      "  File \"/home/mithrillion/anaconda3/lib/python3.5/dbm/dumb.py\", line 124, in _commit\n",
      "    self._chmod(self._dirfile)\n",
      "  File \"/home/mithrillion/anaconda3/lib/python3.5/dbm/dumb.py\", line 270, in _chmod\n",
      "    self._os.chmod(file, self._mode)\n",
      "FileNotFoundError: [Errno 2] No such file or directory: 'models/area3/shelves/old/pixels.dir'\n",
      "Exception ignored in: <bound method Shelf.__del__ of <shelve.DbfilenameShelf object at 0x7f0ba3ff17f0>>\n",
      "Traceback (most recent call last):\n",
      "  File \"/home/mithrillion/anaconda3/lib/python3.5/shelve.py\", line 162, in __del__\n",
      "    self.close()\n",
      "  File \"/home/mithrillion/anaconda3/lib/python3.5/shelve.py\", line 144, in close\n",
      "    self.sync()\n",
      "  File \"/home/mithrillion/anaconda3/lib/python3.5/shelve.py\", line 172, in sync\n",
      "Exception ignored in: <bound method Shelf.__del__ of <shelve.DbfilenameShelf object at 0x7f0ba3fe6c88>>\n",
      "Exception ignored in: <bound method Shelf.__del__ of <shelve.DbfilenameShelf object at 0x7f0ba3ff1860>>\n",
      "    self.dict.sync()\n",
      "  File \"/home/mithrillion/anaconda3/lib/python3.5/dbm/dumb.py\", line 124, in _commit\n",
      "Traceback (most recent call last):\n",
      "Traceback (most recent call last):\n",
      "  File \"/home/mithrillion/anaconda3/lib/python3.5/shelve.py\", line 162, in __del__\n",
      "  File \"/home/mithrillion/anaconda3/lib/python3.5/shelve.py\", line 162, in __del__\n",
      "    self._chmod(self._dirfile)\n",
      "    self.close()\n",
      "  File \"/home/mithrillion/anaconda3/lib/python3.5/dbm/dumb.py\", line 270, in _chmod\n",
      "  File \"/home/mithrillion/anaconda3/lib/python3.5/shelve.py\", line 144, in close\n",
      "    self._os.chmod(file, self._mode)\n",
      "    self.sync()\n",
      "  File \"/home/mithrillion/anaconda3/lib/python3.5/shelve.py\", line 172, in sync\n",
      "FileNotFoundError: [Errno 2] No such file or directory: 'models/area3/shelves/old/pixels.dir'\n",
      "    self.dict.sync()\n",
      "  File \"/home/mithrillion/anaconda3/lib/python3.5/dbm/dumb.py\", line 124, in _commit\n",
      "    self._chmod(self._dirfile)\n",
      "  File \"/home/mithrillion/anaconda3/lib/python3.5/dbm/dumb.py\", line 270, in _chmod\n",
      "    self.close()\n",
      "    self._os.chmod(file, self._mode)\n",
      "FileNotFoundError: [Errno 2] No such file or directory: 'models/area3/shelves/old/pixels.dir'\n",
      "  File \"/home/mithrillion/anaconda3/lib/python3.5/shelve.py\", line 144, in close\n",
      "    self.sync()\n",
      "  File \"/home/mithrillion/anaconda3/lib/python3.5/shelve.py\", line 172, in sync\n",
      "    self.dict.sync()\n",
      "  File \"/home/mithrillion/anaconda3/lib/python3.5/dbm/dumb.py\", line 124, in _commit\n",
      "    self._chmod(self._dirfile)\n",
      "  File \"/home/mithrillion/anaconda3/lib/python3.5/dbm/dumb.py\", line 270, in _chmod\n",
      "    self._os.chmod(file, self._mode)\n",
      "FileNotFoundError: [Errno 2] No such file or directory: 'models/area3/shelves/old/pixels.dir'\n",
      "Exception ignored in: <bound method Shelf.__del__ of <shelve.DbfilenameShelf object at 0x7f0bbdd8d400>>\n",
      "Traceback (most recent call last):\n",
      "  File \"/home/mithrillion/anaconda3/lib/python3.5/shelve.py\", line 162, in __del__\n",
      "    self.close()\n",
      "  File \"/home/mithrillion/anaconda3/lib/python3.5/shelve.py\", line 146, in close\n",
      "    self.dict.close()\n",
      "  File \"/home/mithrillion/anaconda3/lib/python3.5/dbm/dumb.py\", line 262, in close\n",
      "    self._commit()\n",
      "  File \"/home/mithrillion/anaconda3/lib/python3.5/dbm/dumb.py\", line 124, in _commit\n",
      "    self._chmod(self._dirfile)\n",
      "  File \"/home/mithrillion/anaconda3/lib/python3.5/dbm/dumb.py\", line 270, in _chmod\n",
      "    self._os.chmod(file, self._mode)\n",
      "FileNotFoundError: [Errno 2] No such file or directory: 'models/area3/shelves/old/pixels.dir'\n",
      "Exception ignored in: <bound method Shelf.__del__ of <shelve.DbfilenameShelf object at 0x7f0ba3ff1780>>\n",
      "Traceback (most recent call last):\n",
      "Exception ignored in: <bound method Shelf.__del__ of <shelve.DbfilenameShelf object at 0x7f0ba3ff1f28>>\n",
      "  File \"/home/mithrillion/anaconda3/lib/python3.5/shelve.py\", line 162, in __del__\n",
      "    self.close()\n",
      "  File \"/home/mithrillion/anaconda3/lib/python3.5/shelve.py\", line 146, in close\n",
      "    self.dict.close()\n",
      "Traceback (most recent call last):\n",
      "  File \"/home/mithrillion/anaconda3/lib/python3.5/dbm/dumb.py\", line 262, in close\n",
      "  File \"/home/mithrillion/anaconda3/lib/python3.5/shelve.py\", line 162, in __del__\n",
      "    self.close()\n",
      "  File \"/home/mithrillion/anaconda3/lib/python3.5/shelve.py\", line 144, in close\n",
      "    self.sync()\n",
      "  File \"/home/mithrillion/anaconda3/lib/python3.5/shelve.py\", line 172, in sync\n",
      "    self.dict.sync()\n",
      "  File \"/home/mithrillion/anaconda3/lib/python3.5/dbm/dumb.py\", line 124, in _commit\n",
      "    self._chmod(self._dirfile)\n",
      "    self._commit()\n",
      "  File \"/home/mithrillion/anaconda3/lib/python3.5/dbm/dumb.py\", line 270, in _chmod\n",
      "    self._os.chmod(file, self._mode)\n",
      "  File \"/home/mithrillion/anaconda3/lib/python3.5/dbm/dumb.py\", line 124, in _commit\n",
      "FileNotFoundError: [Errno 2] No such file or directory: 'models/area3/shelves/old/pixels.dir'\n",
      "    self._chmod(self._dirfile)\n",
      "  File \"/home/mithrillion/anaconda3/lib/python3.5/dbm/dumb.py\", line 270, in _chmod\n",
      "    self._os.chmod(file, self._mode)\n",
      "FileNotFoundError: [Errno 2] No such file or directory: 'models/area3/shelves/old/pixels.dir'\n",
      "Exception ignored in: <bound method Shelf.__del__ of <shelve.DbfilenameShelf object at 0x7f0ba4056208>>\n",
      "Traceback (most recent call last):\n",
      "  File \"/home/mithrillion/anaconda3/lib/python3.5/shelve.py\", line 162, in __del__\n",
      "    self.close()\n",
      "  File \"/home/mithrillion/anaconda3/lib/python3.5/shelve.py\", line 144, in close\n",
      "    self.sync()\n",
      "  File \"/home/mithrillion/anaconda3/lib/python3.5/shelve.py\", line 172, in sync\n",
      "    self.dict.sync()\n",
      "  File \"/home/mithrillion/anaconda3/lib/python3.5/dbm/dumb.py\", line 124, in _commit\n",
      "    self._chmod(self._dirfile)\n",
      "  File \"/home/mithrillion/anaconda3/lib/python3.5/dbm/dumb.py\", line 270, in _chmod\n",
      "    self._os.chmod(file, self._mode)\n",
      "FileNotFoundError: [Errno 2] No such file or directory: 'models/area3/shelves/old/pixels.dir'\n",
      "Exception ignored in: <bound method Shelf.__del__ of <shelve.DbfilenameShelf object at 0x7f0ba3ff1860>>\n",
      "Exception ignored in: <bound method Shelf.__del__ of <shelve.DbfilenameShelf object at 0x7f0ba3ff6d68>>\n",
      "Exception ignored in: <bound method Shelf.__del__ of <shelve.DbfilenameShelf object at 0x7f0ba3ff19b0>>\n",
      "Exception ignored in: <bound method Shelf.__del__ of <shelve.DbfilenameShelf object at 0x7f0ba3ff1898>>\n",
      "Traceback (most recent call last):\n",
      "Traceback (most recent call last):\n",
      "  File \"/home/mithrillion/anaconda3/lib/python3.5/shelve.py\", line 162, in __del__\n",
      "  File \"/home/mithrillion/anaconda3/lib/python3.5/shelve.py\", line 162, in __del__\n",
      "    self.close()\n",
      "  File \"/home/mithrillion/anaconda3/lib/python3.5/shelve.py\", line 144, in close\n",
      "Traceback (most recent call last):\n",
      "Traceback (most recent call last):\n",
      "  File \"/home/mithrillion/anaconda3/lib/python3.5/shelve.py\", line 162, in __del__\n",
      "    self.sync()\n",
      "  File \"/home/mithrillion/anaconda3/lib/python3.5/shelve.py\", line 162, in __del__\n",
      "  File \"/home/mithrillion/anaconda3/lib/python3.5/shelve.py\", line 172, in sync\n",
      "    self.close()\n",
      "    self.dict.sync()\n",
      "  File \"/home/mithrillion/anaconda3/lib/python3.5/dbm/dumb.py\", line 124, in _commit\n",
      "  File \"/home/mithrillion/anaconda3/lib/python3.5/shelve.py\", line 146, in close\n",
      "    self.close()\n",
      "    self._chmod(self._dirfile)\n",
      "  File \"/home/mithrillion/anaconda3/lib/python3.5/shelve.py\", line 146, in close\n",
      "    self.dict.close()\n",
      "    self.close()\n",
      "  File \"/home/mithrillion/anaconda3/lib/python3.5/dbm/dumb.py\", line 270, in _chmod\n",
      "  File \"/home/mithrillion/anaconda3/lib/python3.5/dbm/dumb.py\", line 262, in close\n",
      "  File \"/home/mithrillion/anaconda3/lib/python3.5/shelve.py\", line 144, in close\n",
      "    self.dict.close()\n",
      "    self.sync()\n",
      "  File \"/home/mithrillion/anaconda3/lib/python3.5/dbm/dumb.py\", line 262, in close\n",
      "  File \"/home/mithrillion/anaconda3/lib/python3.5/shelve.py\", line 172, in sync\n",
      "    self._commit()\n",
      "    self._os.chmod(file, self._mode)\n",
      "    self._commit()\n",
      "  File \"/home/mithrillion/anaconda3/lib/python3.5/dbm/dumb.py\", line 124, in _commit\n",
      "    self.dict.sync()\n",
      "  File \"/home/mithrillion/anaconda3/lib/python3.5/dbm/dumb.py\", line 124, in _commit\n",
      "FileNotFoundError: [Errno 2] No such file or directory: 'models/area3/shelves/old/pixels.dir'\n",
      "  File \"/home/mithrillion/anaconda3/lib/python3.5/dbm/dumb.py\", line 124, in _commit\n",
      "    self._chmod(self._dirfile)\n",
      "    self._chmod(self._dirfile)\n",
      "  File \"/home/mithrillion/anaconda3/lib/python3.5/dbm/dumb.py\", line 270, in _chmod\n",
      "    self._chmod(self._dirfile)\n",
      "  File \"/home/mithrillion/anaconda3/lib/python3.5/dbm/dumb.py\", line 270, in _chmod\n",
      "  File \"/home/mithrillion/anaconda3/lib/python3.5/dbm/dumb.py\", line 270, in _chmod\n",
      "    self._os.chmod(file, self._mode)\n",
      "    self._os.chmod(file, self._mode)\n",
      "    self._os.chmod(file, self._mode)\n",
      "FileNotFoundError: [Errno 2] No such file or directory: 'models/area3/shelves/old/pixels.dir'\n",
      "FileNotFoundError: [Errno 2] No such file or directory: 'models/area3/shelves/old/pixels.dir'\n",
      "FileNotFoundError: [Errno 2] No such file or directory: 'models/area3/shelves/old/pixels.dir'\n",
      "Exception ignored in: <bound method Shelf.__del__ of <shelve.DbfilenameShelf object at 0x7f0ba3ff1a20>>\n",
      "Exception ignored in: <bound method Shelf.__del__ of <shelve.DbfilenameShelf object at 0x7f0ba3ff17f0>>\n",
      "Traceback (most recent call last):\n",
      "Traceback (most recent call last):\n",
      "  File \"/home/mithrillion/anaconda3/lib/python3.5/shelve.py\", line 162, in __del__\n",
      "  File \"/home/mithrillion/anaconda3/lib/python3.5/shelve.py\", line 162, in __del__\n",
      "    self.close()\n",
      "  File \"/home/mithrillion/anaconda3/lib/python3.5/shelve.py\", line 144, in close\n",
      "    self.sync()\n",
      "    self.close()\n",
      "  File \"/home/mithrillion/anaconda3/lib/python3.5/shelve.py\", line 172, in sync\n",
      "  File \"/home/mithrillion/anaconda3/lib/python3.5/shelve.py\", line 144, in close\n",
      "    self.dict.sync()\n",
      "  File \"/home/mithrillion/anaconda3/lib/python3.5/dbm/dumb.py\", line 124, in _commit\n",
      "    self.sync()\n",
      "  File \"/home/mithrillion/anaconda3/lib/python3.5/shelve.py\", line 172, in sync\n",
      "    self.dict.sync()\n",
      "    self._chmod(self._dirfile)\n",
      "  File \"/home/mithrillion/anaconda3/lib/python3.5/dbm/dumb.py\", line 124, in _commit\n",
      "    self._chmod(self._dirfile)\n",
      "  File \"/home/mithrillion/anaconda3/lib/python3.5/dbm/dumb.py\", line 270, in _chmod\n",
      "    self._os.chmod(file, self._mode)\n",
      "FileNotFoundError: [Errno 2] No such file or directory: 'models/area3/shelves/old/pixels.dir'\n",
      "  File \"/home/mithrillion/anaconda3/lib/python3.5/dbm/dumb.py\", line 270, in _chmod\n",
      "    self._os.chmod(file, self._mode)\n",
      "FileNotFoundError: [Errno 2] No such file or directory: 'models/area3/shelves/old/pixels.dir'\n",
      "Exception ignored in: <bound method Shelf.__del__ of <shelve.DbfilenameShelf object at 0x7f0ba3ff6240>>\n",
      "Traceback (most recent call last):\n",
      "  File \"/home/mithrillion/anaconda3/lib/python3.5/shelve.py\", line 162, in __del__\n",
      "    self.close()\n",
      "  File \"/home/mithrillion/anaconda3/lib/python3.5/shelve.py\", line 144, in close\n",
      "    self.sync()\n",
      "  File \"/home/mithrillion/anaconda3/lib/python3.5/shelve.py\", line 172, in sync\n",
      "    self.dict.sync()\n",
      "  File \"/home/mithrillion/anaconda3/lib/python3.5/dbm/dumb.py\", line 124, in _commit\n",
      "    self._chmod(self._dirfile)\n",
      "  File \"/home/mithrillion/anaconda3/lib/python3.5/dbm/dumb.py\", line 270, in _chmod\n",
      "    self._os.chmod(file, self._mode)\n",
      "FileNotFoundError: [Errno 2] No such file or directory: 'models/area3/shelves/old/pixels.dir'\n",
      "Exception ignored in: <bound method Shelf.__del__ of <shelve.DbfilenameShelf object at 0x7f0ba3ff6828>>\n",
      "Traceback (most recent call last):\n",
      "  File \"/home/mithrillion/anaconda3/lib/python3.5/shelve.py\", line 162, in __del__\n",
      "    self.close()\n",
      "  File \"/home/mithrillion/anaconda3/lib/python3.5/shelve.py\", line 146, in close\n",
      "    self.dict.close()\n",
      "  File \"/home/mithrillion/anaconda3/lib/python3.5/dbm/dumb.py\", line 262, in close\n",
      "    self._commit()\n",
      "  File \"/home/mithrillion/anaconda3/lib/python3.5/dbm/dumb.py\", line 124, in _commit\n",
      "    self._chmod(self._dirfile)\n",
      "  File \"/home/mithrillion/anaconda3/lib/python3.5/dbm/dumb.py\", line 270, in _chmod\n",
      "    self._os.chmod(file, self._mode)\n",
      "FileNotFoundError: [Errno 2] No such file or directory: 'models/area3/shelves/old/pixels.dir'\n",
      "Exception ignored in: <bound method Shelf.__del__ of <shelve.DbfilenameShelf object at 0x7f0ba3ff1898>>\n",
      "Traceback (most recent call last):\n",
      "  File \"/home/mithrillion/anaconda3/lib/python3.5/shelve.py\", line 162, in __del__\n",
      "    self.close()\n",
      "  File \"/home/mithrillion/anaconda3/lib/python3.5/shelve.py\", line 146, in close\n",
      "    self.dict.close()\n",
      "  File \"/home/mithrillion/anaconda3/lib/python3.5/dbm/dumb.py\", line 262, in close\n",
      "    self._commit()\n",
      "  File \"/home/mithrillion/anaconda3/lib/python3.5/dbm/dumb.py\", line 124, in _commit\n",
      "    self._chmod(self._dirfile)\n",
      "  File \"/home/mithrillion/anaconda3/lib/python3.5/dbm/dumb.py\", line 270, in _chmod\n",
      "    self._os.chmod(file, self._mode)\n",
      "FileNotFoundError: [Errno 2] No such file or directory: 'models/area3/shelves/old/pixels.dir'\n",
      "Exception ignored in: <bound method Shelf.__del__ of <shelve.DbfilenameShelf object at 0x7f0bbdd8d9b0>>\n",
      "Exception ignored in: <bound method Shelf.__del__ of <shelve.DbfilenameShelf object at 0x7f0bbdd8dbe0>>\n",
      "Traceback (most recent call last):\n",
      "  File \"/home/mithrillion/anaconda3/lib/python3.5/shelve.py\", line 162, in __del__\n",
      "    self.close()\n",
      "  File \"/home/mithrillion/anaconda3/lib/python3.5/shelve.py\", line 146, in close\n",
      "Traceback (most recent call last):\n",
      "    self.dict.close()\n",
      "  File \"/home/mithrillion/anaconda3/lib/python3.5/shelve.py\", line 162, in __del__\n",
      "  File \"/home/mithrillion/anaconda3/lib/python3.5/dbm/dumb.py\", line 262, in close\n",
      "    self._commit()\n",
      "    self.close()\n",
      "  File \"/home/mithrillion/anaconda3/lib/python3.5/dbm/dumb.py\", line 124, in _commit\n",
      "  File \"/home/mithrillion/anaconda3/lib/python3.5/shelve.py\", line 144, in close\n",
      "    self.sync()\n",
      "  File \"/home/mithrillion/anaconda3/lib/python3.5/shelve.py\", line 172, in sync\n",
      "    self.dict.sync()\n",
      "  File \"/home/mithrillion/anaconda3/lib/python3.5/dbm/dumb.py\", line 124, in _commit\n",
      "    self._chmod(self._dirfile)\n",
      "    self._chmod(self._dirfile)\n",
      "  File \"/home/mithrillion/anaconda3/lib/python3.5/dbm/dumb.py\", line 270, in _chmod\n",
      "  File \"/home/mithrillion/anaconda3/lib/python3.5/dbm/dumb.py\", line 270, in _chmod\n",
      "    self._os.chmod(file, self._mode)\n",
      "FileNotFoundError: [Errno 2] No such file or directory: 'models/area3/shelves/old/pixels.dir'\n",
      "    self._os.chmod(file, self._mode)\n",
      "FileNotFoundError: [Errno 2] No such file or directory: 'models/area3/shelves/old/pixels.dir'\n",
      "Exception ignored in: <bound method Shelf.__del__ of <shelve.DbfilenameShelf object at 0x7f0ba3ff1dd8>>\n",
      "Traceback (most recent call last):\n",
      "  File \"/home/mithrillion/anaconda3/lib/python3.5/shelve.py\", line 162, in __del__\n",
      "    self.close()\n",
      "  File \"/home/mithrillion/anaconda3/lib/python3.5/shelve.py\", line 146, in close\n",
      "    self.dict.close()\n",
      "  File \"/home/mithrillion/anaconda3/lib/python3.5/dbm/dumb.py\", line 262, in close\n",
      "    self._commit()\n",
      "  File \"/home/mithrillion/anaconda3/lib/python3.5/dbm/dumb.py\", line 124, in _commit\n",
      "    self._chmod(self._dirfile)\n",
      "  File \"/home/mithrillion/anaconda3/lib/python3.5/dbm/dumb.py\", line 270, in _chmod\n",
      "    self._os.chmod(file, self._mode)\n",
      "FileNotFoundError: [Errno 2] No such file or directory: 'models/area3/shelves/old/pixels.dir'\n",
      "Exception ignored in: <bound method Shelf.__del__ of <shelve.DbfilenameShelf object at 0x7f0ba3ff6e80>>\n",
      "Traceback (most recent call last):\n",
      "  File \"/home/mithrillion/anaconda3/lib/python3.5/shelve.py\", line 162, in __del__\n",
      "    self.close()\n",
      "  File \"/home/mithrillion/anaconda3/lib/python3.5/shelve.py\", line 146, in close\n",
      "    self.dict.close()\n",
      "  File \"/home/mithrillion/anaconda3/lib/python3.5/dbm/dumb.py\", line 262, in close\n",
      "    self._commit()\n",
      "  File \"/home/mithrillion/anaconda3/lib/python3.5/dbm/dumb.py\", line 124, in _commit\n",
      "    self._chmod(self._dirfile)\n",
      "  File \"/home/mithrillion/anaconda3/lib/python3.5/dbm/dumb.py\", line 270, in _chmod\n",
      "    self._os.chmod(file, self._mode)\n",
      "FileNotFoundError: [Errno 2] No such file or directory: 'models/area3/shelves/old/pixels.dir'\n",
      "Exception ignored in: <bound method Shelf.__del__ of <shelve.DbfilenameShelf object at 0x7f0ba3ff1898>>\n",
      "Traceback (most recent call last):\n",
      "  File \"/home/mithrillion/anaconda3/lib/python3.5/shelve.py\", line 162, in __del__\n",
      "    self.close()\n",
      "  File \"/home/mithrillion/anaconda3/lib/python3.5/shelve.py\", line 144, in close\n",
      "    self.sync()\n",
      "  File \"/home/mithrillion/anaconda3/lib/python3.5/shelve.py\", line 172, in sync\n",
      "    self.dict.sync()\n",
      "  File \"/home/mithrillion/anaconda3/lib/python3.5/dbm/dumb.py\", line 124, in _commit\n",
      "    self._chmod(self._dirfile)\n",
      "  File \"/home/mithrillion/anaconda3/lib/python3.5/dbm/dumb.py\", line 270, in _chmod\n",
      "    self._os.chmod(file, self._mode)\n",
      "FileNotFoundError: [Errno 2] No such file or directory: 'models/area3/shelves/old/pixels.dir'\n",
      "Exception ignored in: <bound method Shelf.__del__ of <shelve.DbfilenameShelf object at 0x7f0ba3ff6630>>\n",
      "Exception ignored in: <bound method Shelf.__del__ of <shelve.DbfilenameShelf object at 0x7f0ba3ff6e80>>\n",
      "Traceback (most recent call last):\n",
      "Traceback (most recent call last):\n",
      "  File \"/home/mithrillion/anaconda3/lib/python3.5/shelve.py\", line 162, in __del__\n",
      "  File \"/home/mithrillion/anaconda3/lib/python3.5/shelve.py\", line 162, in __del__\n",
      "    self.close()\n",
      "    self.close()\n",
      "  File \"/home/mithrillion/anaconda3/lib/python3.5/shelve.py\", line 144, in close\n",
      "  File \"/home/mithrillion/anaconda3/lib/python3.5/shelve.py\", line 144, in close\n",
      "    self.sync()\n",
      "    self.sync()\n",
      "  File \"/home/mithrillion/anaconda3/lib/python3.5/shelve.py\", line 172, in sync\n",
      "  File \"/home/mithrillion/anaconda3/lib/python3.5/shelve.py\", line 172, in sync\n",
      "    self.dict.sync()\n",
      "Exception ignored in: <bound method Shelf.__del__ of <shelve.DbfilenameShelf object at 0x7f0ba3ff6e80>>\n",
      "Traceback (most recent call last):\n",
      "  File \"/home/mithrillion/anaconda3/lib/python3.5/shelve.py\", line 162, in __del__\n",
      "    self.close()\n",
      "  File \"/home/mithrillion/anaconda3/lib/python3.5/shelve.py\", line 144, in close\n",
      "    self.sync()\n",
      "  File \"/home/mithrillion/anaconda3/lib/python3.5/dbm/dumb.py\", line 124, in _commit\n",
      "    self._chmod(self._dirfile)\n",
      "  File \"/home/mithrillion/anaconda3/lib/python3.5/dbm/dumb.py\", line 270, in _chmod\n",
      "    self._os.chmod(file, self._mode)\n",
      "FileNotFoundError: [Errno 2] No such file or directory: 'models/area3/shelves/old/pixels.dir'\n",
      "  File \"/home/mithrillion/anaconda3/lib/python3.5/shelve.py\", line 172, in sync\n",
      "Exception ignored in: <bound method Shelf.__del__ of <shelve.DbfilenameShelf object at 0x7f0bbdd8dd30>>\n",
      "    self.dict.sync()\n",
      "  File \"/home/mithrillion/anaconda3/lib/python3.5/dbm/dumb.py\", line 124, in _commit\n",
      "    self._chmod(self._dirfile)\n",
      "  File \"/home/mithrillion/anaconda3/lib/python3.5/dbm/dumb.py\", line 270, in _chmod\n",
      "    self.dict.sync()\n",
      "  File \"/home/mithrillion/anaconda3/lib/python3.5/dbm/dumb.py\", line 124, in _commit\n",
      "    self._chmod(self._dirfile)\n",
      "  File \"/home/mithrillion/anaconda3/lib/python3.5/dbm/dumb.py\", line 270, in _chmod\n",
      "    self._os.chmod(file, self._mode)\n",
      "FileNotFoundError: [Errno 2] No such file or directory: 'models/area3/shelves/old/pixels.dir'\n",
      "    self._os.chmod(file, self._mode)\n",
      "FileNotFoundError: [Errno 2] No such file or directory: 'models/area3/shelves/old/pixels.dir'\n",
      "Traceback (most recent call last):\n",
      "  File \"/home/mithrillion/anaconda3/lib/python3.5/shelve.py\", line 162, in __del__\n",
      "    self.close()\n",
      "  File \"/home/mithrillion/anaconda3/lib/python3.5/shelve.py\", line 146, in close\n",
      "    self.dict.close()\n",
      "  File \"/home/mithrillion/anaconda3/lib/python3.5/dbm/dumb.py\", line 262, in close\n",
      "    self._commit()\n",
      "  File \"/home/mithrillion/anaconda3/lib/python3.5/dbm/dumb.py\", line 124, in _commit\n",
      "    self._chmod(self._dirfile)\n",
      "  File \"/home/mithrillion/anaconda3/lib/python3.5/dbm/dumb.py\", line 270, in _chmod\n",
      "    self._os.chmod(file, self._mode)\n",
      "FileNotFoundError: [Errno 2] No such file or directory: 'models/area3/shelves/old/pixels.dir'\n",
      "Exception ignored in: <bound method Shelf.__del__ of <shelve.DbfilenameShelf object at 0x7f0ba3ff6e10>>\n",
      "Exception ignored in: <bound method Shelf.__del__ of <shelve.DbfilenameShelf object at 0x7f0ba3ff1898>>\n",
      "Traceback (most recent call last):\n",
      "Exception ignored in: <bound method Shelf.__del__ of <shelve.DbfilenameShelf object at 0x7f0ba3ff1048>>\n",
      "Traceback (most recent call last):\n",
      "Traceback (most recent call last):\n",
      "  File \"/home/mithrillion/anaconda3/lib/python3.5/shelve.py\", line 162, in __del__\n",
      "  File \"/home/mithrillion/anaconda3/lib/python3.5/shelve.py\", line 162, in __del__\n",
      "    self.close()\n",
      "    self.close()\n",
      "  File \"/home/mithrillion/anaconda3/lib/python3.5/shelve.py\", line 146, in close\n",
      "    self.dict.close()\n",
      "  File \"/home/mithrillion/anaconda3/lib/python3.5/dbm/dumb.py\", line 262, in close\n",
      "    self._commit()\n",
      "  File \"/home/mithrillion/anaconda3/lib/python3.5/dbm/dumb.py\", line 124, in _commit\n",
      "  File \"/home/mithrillion/anaconda3/lib/python3.5/shelve.py\", line 146, in close\n",
      "  File \"/home/mithrillion/anaconda3/lib/python3.5/shelve.py\", line 162, in __del__\n",
      "    self.dict.close()\n",
      "    self._chmod(self._dirfile)\n",
      "    self.close()\n",
      "  File \"/home/mithrillion/anaconda3/lib/python3.5/dbm/dumb.py\", line 262, in close\n",
      "  File \"/home/mithrillion/anaconda3/lib/python3.5/shelve.py\", line 146, in close\n",
      "    self._commit()\n",
      "    self.dict.close()\n",
      "  File \"/home/mithrillion/anaconda3/lib/python3.5/dbm/dumb.py\", line 124, in _commit\n",
      "  File \"/home/mithrillion/anaconda3/lib/python3.5/dbm/dumb.py\", line 262, in close\n",
      "    self._chmod(self._dirfile)\n",
      "    self._commit()\n",
      "  File \"/home/mithrillion/anaconda3/lib/python3.5/dbm/dumb.py\", line 270, in _chmod\n",
      "  File \"/home/mithrillion/anaconda3/lib/python3.5/dbm/dumb.py\", line 124, in _commit\n",
      "    self._os.chmod(file, self._mode)\n",
      "FileNotFoundError: [Errno 2] No such file or directory: 'models/area3/shelves/old/pixels.dir'\n",
      "    self._chmod(self._dirfile)\n",
      "  File \"/home/mithrillion/anaconda3/lib/python3.5/dbm/dumb.py\", line 270, in _chmod\n",
      "    self._os.chmod(file, self._mode)\n",
      "FileNotFoundError: [Errno 2] No such file or directory: 'models/area3/shelves/old/pixels.dir'\n",
      "  File \"/home/mithrillion/anaconda3/lib/python3.5/dbm/dumb.py\", line 270, in _chmod\n",
      "    self._os.chmod(file, self._mode)\n",
      "FileNotFoundError: [Errno 2] No such file or directory: 'models/area3/shelves/old/pixels.dir'\n",
      "Exception ignored in: <bound method Shelf.__del__ of <shelve.DbfilenameShelf object at 0x7f0ba3ff67f0>>\n",
      "Exception ignored in: <bound method Shelf.__del__ of <shelve.DbfilenameShelf object at 0x7f0ba3ff6780>>\n",
      "Exception ignored in: <bound method Shelf.__del__ of <shelve.DbfilenameShelf object at 0x7f0ba4056080>>\n",
      "Exception ignored in: <bound method Shelf.__del__ of <shelve.DbfilenameShelf object at 0x7f0ba3ff6898>>\n",
      "Traceback (most recent call last):\n",
      "Traceback (most recent call last):\n",
      "Traceback (most recent call last):\n",
      "Traceback (most recent call last):\n",
      "  File \"/home/mithrillion/anaconda3/lib/python3.5/shelve.py\", line 162, in __del__\n",
      "  File \"/home/mithrillion/anaconda3/lib/python3.5/shelve.py\", line 162, in __del__\n",
      "  File \"/home/mithrillion/anaconda3/lib/python3.5/shelve.py\", line 162, in __del__\n",
      "    self.close()\n",
      "    self.close()\n",
      "  File \"/home/mithrillion/anaconda3/lib/python3.5/shelve.py\", line 144, in close\n",
      "    self.sync()\n",
      "  File \"/home/mithrillion/anaconda3/lib/python3.5/shelve.py\", line 172, in sync\n",
      "    self.dict.sync()\n",
      "  File \"/home/mithrillion/anaconda3/lib/python3.5/dbm/dumb.py\", line 124, in _commit\n",
      "    self._chmod(self._dirfile)\n",
      "  File \"/home/mithrillion/anaconda3/lib/python3.5/dbm/dumb.py\", line 270, in _chmod\n",
      "    self.close()\n",
      "  File \"/home/mithrillion/anaconda3/lib/python3.5/shelve.py\", line 146, in close\n",
      "  File \"/home/mithrillion/anaconda3/lib/python3.5/shelve.py\", line 162, in __del__\n",
      "    self._os.chmod(file, self._mode)\n",
      "  File \"/home/mithrillion/anaconda3/lib/python3.5/shelve.py\", line 144, in close\n",
      "FileNotFoundError: [Errno 2] No such file or directory: 'models/area3/shelves/old/pixels.dir'\n",
      "    self.close()\n",
      "    self.sync()\n",
      "  File \"/home/mithrillion/anaconda3/lib/python3.5/shelve.py\", line 172, in sync\n",
      "    self.dict.close()\n",
      "  File \"/home/mithrillion/anaconda3/lib/python3.5/shelve.py\", line 144, in close\n",
      "    self.dict.sync()\n",
      "  File \"/home/mithrillion/anaconda3/lib/python3.5/dbm/dumb.py\", line 262, in close\n",
      "    self.sync()\n",
      "  File \"/home/mithrillion/anaconda3/lib/python3.5/dbm/dumb.py\", line 124, in _commit\n",
      "  File \"/home/mithrillion/anaconda3/lib/python3.5/shelve.py\", line 172, in sync\n",
      "    self._commit()\n",
      "    self._chmod(self._dirfile)\n",
      "  File \"/home/mithrillion/anaconda3/lib/python3.5/dbm/dumb.py\", line 124, in _commit\n",
      "    self.dict.sync()\n",
      "  File \"/home/mithrillion/anaconda3/lib/python3.5/dbm/dumb.py\", line 124, in _commit\n",
      "  File \"/home/mithrillion/anaconda3/lib/python3.5/dbm/dumb.py\", line 270, in _chmod\n",
      "    self._chmod(self._dirfile)\n",
      "    self._os.chmod(file, self._mode)\n",
      "  File \"/home/mithrillion/anaconda3/lib/python3.5/dbm/dumb.py\", line 270, in _chmod\n",
      "FileNotFoundError: [Errno 2] No such file or directory: 'models/area3/shelves/old/pixels.dir'\n",
      "    self._chmod(self._dirfile)\n",
      "    self._os.chmod(file, self._mode)\n",
      "  File \"/home/mithrillion/anaconda3/lib/python3.5/dbm/dumb.py\", line 270, in _chmod\n",
      "FileNotFoundError: [Errno 2] No such file or directory: 'models/area3/shelves/old/pixels.dir'\n",
      "    self._os.chmod(file, self._mode)\n",
      "FileNotFoundError: [Errno 2] No such file or directory: 'models/area3/shelves/old/pixels.dir'\n",
      "Exception ignored in: <bound method Shelf.__del__ of <shelve.DbfilenameShelf object at 0x7f0ba3ff1860>>\n",
      "Exception ignored in: <bound method Shelf.__del__ of <shelve.DbfilenameShelf object at 0x7f0ba3ff1898>>\n",
      "Traceback (most recent call last):\n",
      "  File \"/home/mithrillion/anaconda3/lib/python3.5/shelve.py\", line 162, in __del__\n",
      "    self.close()\n",
      "  File \"/home/mithrillion/anaconda3/lib/python3.5/shelve.py\", line 144, in close\n",
      "    self.sync()\n",
      "  File \"/home/mithrillion/anaconda3/lib/python3.5/shelve.py\", line 172, in sync\n",
      "    self.dict.sync()\n",
      "  File \"/home/mithrillion/anaconda3/lib/python3.5/dbm/dumb.py\", line 124, in _commit\n",
      "    self._chmod(self._dirfile)\n",
      "  File \"/home/mithrillion/anaconda3/lib/python3.5/dbm/dumb.py\", line 270, in _chmod\n",
      "    self._os.chmod(file, self._mode)\n",
      "Traceback (most recent call last):\n",
      "FileNotFoundError: [Errno 2] No such file or directory: 'models/area3/shelves/old/pixels.dir'\n",
      "  File \"/home/mithrillion/anaconda3/lib/python3.5/shelve.py\", line 162, in __del__\n",
      "    self.close()\n",
      "  File \"/home/mithrillion/anaconda3/lib/python3.5/shelve.py\", line 144, in close\n",
      "    self.sync()\n",
      "  File \"/home/mithrillion/anaconda3/lib/python3.5/shelve.py\", line 172, in sync\n",
      "    self.dict.sync()\n",
      "  File \"/home/mithrillion/anaconda3/lib/python3.5/dbm/dumb.py\", line 124, in _commit\n",
      "    self._chmod(self._dirfile)\n",
      "  File \"/home/mithrillion/anaconda3/lib/python3.5/dbm/dumb.py\", line 270, in _chmod\n",
      "    self._os.chmod(file, self._mode)\n",
      "FileNotFoundError: [Errno 2] No such file or directory: 'models/area3/shelves/old/pixels.dir'\n",
      "Exception ignored in: <bound method Shelf.__del__ of <shelve.DbfilenameShelf object at 0x7f0ba3ff6898>>\n",
      "Traceback (most recent call last):\n",
      "  File \"/home/mithrillion/anaconda3/lib/python3.5/shelve.py\", line 162, in __del__\n",
      "    self.close()\n",
      "  File \"/home/mithrillion/anaconda3/lib/python3.5/shelve.py\", line 146, in close\n",
      "    self.dict.close()\n",
      "  File \"/home/mithrillion/anaconda3/lib/python3.5/dbm/dumb.py\", line 262, in close\n",
      "    self._commit()\n",
      "  File \"/home/mithrillion/anaconda3/lib/python3.5/dbm/dumb.py\", line 124, in _commit\n",
      "    self._chmod(self._dirfile)\n",
      "  File \"/home/mithrillion/anaconda3/lib/python3.5/dbm/dumb.py\", line 270, in _chmod\n",
      "    self._os.chmod(file, self._mode)\n",
      "FileNotFoundError: [Errno 2] No such file or directory: 'models/area3/shelves/old/pixels.dir'\n",
      "Exception ignored in: <bound method Shelf.__del__ of <shelve.DbfilenameShelf object at 0x7f0ba3ff19b0>>\n",
      "Traceback (most recent call last):\n",
      "  File \"/home/mithrillion/anaconda3/lib/python3.5/shelve.py\", line 162, in __del__\n",
      "    self.close()\n",
      "  File \"/home/mithrillion/anaconda3/lib/python3.5/shelve.py\", line 146, in close\n",
      "    self.dict.close()\n",
      "  File \"/home/mithrillion/anaconda3/lib/python3.5/dbm/dumb.py\", line 262, in close\n",
      "    self._commit()\n",
      "  File \"/home/mithrillion/anaconda3/lib/python3.5/dbm/dumb.py\", line 124, in _commit\n",
      "    self._chmod(self._dirfile)\n",
      "  File \"/home/mithrillion/anaconda3/lib/python3.5/dbm/dumb.py\", line 270, in _chmod\n",
      "    self._os.chmod(file, self._mode)\n",
      "FileNotFoundError: [Errno 2] No such file or directory: 'models/area3/shelves/old/pixels.dir'\n"
     ]
    }
   ],
   "source": [
    "train = rid.old_data_preprocess_workflow(image_dir='area3/2014/images/', \n",
    "                                 mask_dir='area3/2014/masks/', \n",
    "                                 table_dir='area3/2014/tables/LC8_SR.csv', \n",
    "                                 new_table_dir='area3/2015/tables/LC8_SR.csv', \n",
    "                                 shelve_root_dir='models/area3/shelves/', \n",
    "                                 labels=array, \n",
    "                                 processes=8, \n",
    "                                 max_days_apart=30, \n",
    "                                 step=250000)"
   ]
  },
  {
   "cell_type": "code",
   "execution_count": null,
   "metadata": {
    "collapsed": true
   },
   "outputs": [],
   "source": []
  }
 ],
 "metadata": {
  "anaconda-cloud": {},
  "kernelspec": {
   "display_name": "Python [Root]",
   "language": "python",
   "name": "Python [Root]"
  },
  "language_info": {
   "codemirror_mode": {
    "name": "ipython",
    "version": 3
   },
   "file_extension": ".py",
   "mimetype": "text/x-python",
   "name": "python",
   "nbconvert_exporter": "python",
   "pygments_lexer": "ipython3",
   "version": "3.5.2"
  }
 },
 "nbformat": 4,
 "nbformat_minor": 0
}
